import unittest
from unittest.mock import patch

import core.network_client


class TestNetworkClient(unittest.TestCase):
    def test_send_request(self):
        """Test sending a network request."""
        try:
            with patch("core.network_client.send_request") as mock_send:
                mock_send.return_value = {"status": 200, "data": "response"}
                result = core.network_client.send_request("GET", "https://example.com")
                self.assertIsInstance(result, dict)
                self.assertEqual(result["status"], 200)
                mock_send.assert_called_once_with("GET", "https://example.com")
        except AttributeError:
            self.skipTest("send_request function not found in core.network_client")

    def test_check_connectivity(self):
        """Test checking network connectivity."""
        try:
            with patch("core.network_client.check_connectivity") as mock_check:
                mock_check.return_value = True
                result = core.network_client.check_connectivity()
                self.assertTrue(result)
                mock_check.assert_called_once()
        except AttributeError:
            self.skipTest(
                "check_connectivity function not found in core.network_client"
            )

    def test_handle_response(self):
        """Test handling network responses."""
        try:
            with patch("core.network_client.handle_response") as mock_handle:
                mock_handle.return_value = {"processed": True, "data": "processed_data"}
                result = core.network_client.handle_response(
                    {"status": 200, "data": "raw_data"}
                )
                self.assertIsInstance(result, dict)
                self.assertTrue(result["processed"])
                mock_handle.assert_called_once_with({"status": 200, "data": "raw_data"})
        except AttributeError:
            self.skipTest("handle_response function not found in core.network_client")

    def test_retry_request(self):
        """Test retrying a failed request."""
        try:
            with patch("core.network_client.retry_request") as mock_retry:
                mock_retry.return_value = {
                    "status": 200,
                    "data": "response_after_retry",
                }
                result = core.network_client.retry_request(
                    "GET", "https://example.com", max_retries=3
                )
                self.assertIsInstance(result, dict)
                self.assertEqual(result["status"], 200)
                mock_retry.assert_called_once_with(
                    "GET", "https://example.com", max_retries=3
                )
        except AttributeError:
            self.skipTest("retry_request function not found in core.network_client")

    def test_validate_endpoint(self):
        """Test validating a network endpoint."""
        try:
            with patch("core.network_client.validate_endpoint") as mock_validate:
                mock_validate.return_value = True
                result = core.network_client.validate_endpoint("https://example.com")
                self.assertTrue(result)
                mock_validate.assert_called_once_with("https://example.com")
        except AttributeError:
            self.skipTest("validate_endpoint function not found in core.network_client")


if __name__ == "__main__":
    unittest.main()
